{
 "cells": [
  {
   "cell_type": "markdown",
   "metadata": {},
   "source": [
    "# 에러 및 예외 처리\n",
    "\n",
    "다음은 파이썬에서 에러 및 예외처리에 관하여 알아보겠습니다. \n",
    "\n",
    "예를 들어 아래와 같은 에러 메시지를 자주 보았을 것입니다:"
   ]
  },
  {
   "cell_type": "code",
   "execution_count": 1,
   "metadata": {},
   "outputs": [
    {
     "ename": "SyntaxError",
     "evalue": "EOL while scanning string literal (<ipython-input-1-683e48a9a7a9>, line 1)",
     "output_type": "error",
     "traceback": [
      "\u001b[0;36m  File \u001b[0;32m\"<ipython-input-1-683e48a9a7a9>\"\u001b[0;36m, line \u001b[0;32m1\u001b[0m\n\u001b[0;31m    print('Hello)\u001b[0m\n\u001b[0m                 ^\u001b[0m\n\u001b[0;31mSyntaxError\u001b[0m\u001b[0;31m:\u001b[0m EOL while scanning string literal\n"
     ]
    }
   ],
   "source": [
    "print('Hello)"
   ]
  },
  {
   "cell_type": "markdown",
   "metadata": {},
   "source": [
    "위에 오류는 한 라인이 끝나기 전에 문자열을 닫아주어야 하는데 그것이 없다는 오류를 보여줍니다. 오류 내용으로 충분히 어디서 잘못되었는지 알 수 있습니다. 여러 다양한 오류나 경고 등이 있는데 이를 잘 이해하고 있다는 것은 더 잘 디버그를 할 수 있다는 것을 의미합니다.\n",
    "\n",
    "이러한 종류의 에러와 에러 설명이 바로 `예외`라고 아시면 됩니다. 때로는 구문이나 문법에 이상이 없다고 하더라도 실행되는 동안 오류가 발생할 수도 있습니다. 실행 하는 동안 발생한 오류가 예외이고 절대적 에러가 아닌 경고일 수도 있습니다. \n",
    "\n",
    "[이곳](https://docs.python.org/3/library/exceptions.html)에 내장 예외에 관한 내용이 있습니다.\n",
    "\n",
    "다음에는 우리의 코드에서 이런 예외를 어떻게 처리하는지 살펴보겠습니다."
   ]
  },
  {
   "cell_type": "markdown",
   "metadata": {},
   "source": [
    "## try 와 except\n",
    "\n",
    "파이썬에서 예외를 다루는 기본 문법은 **try** 와 **except**를 이용하는 구문입니다. 예외를 발생할 수 있는 구문을 포함하는 부분은 *try* 블럭에 넣고 실제 예외가 발생하였을 때 처리하는 부분은 *except* 블럭에 코드를 넣습니다. 구문은 다음과 같습니다:\n",
    "\n",
    "    try:\n",
    "       You do your operations here...\n",
    "       ...\n",
    "    except ExceptionI:\n",
    "       If there is ExceptionI, then execute this block.\n",
    "    except ExceptionII:\n",
    "       If there is ExceptionII, then execute this block.\n",
    "       ...\n",
    "    else:\n",
    "       If there is no exception then execute this block. \n",
    "\n",
    "except 만을 이용하여 모든 예외를 처리하게 할 수도 있습니다. 아래의 예를 이용하여 더 자세히 살펴보겠습니다."
   ]
  },
  {
   "cell_type": "code",
   "execution_count": 2,
   "metadata": {},
   "outputs": [
    {
     "name": "stdout",
     "output_type": "stream",
     "text": [
      "Content written successfully\n"
     ]
    }
   ],
   "source": [
    "f = None\n",
    "try:\n",
    "    f = open('testfile','w')\n",
    "    f.write('Test write this')\n",
    "except IOError:\n",
    "    # This will only check for an IOError exception and then execute this print statement\n",
    "   print(\"Error: Could not find file or read data\")\n",
    "else:\n",
    "   print(\"Content written successfully\")\n",
    "finally:\n",
    "    if \n",
    "    f.close()"
   ]
  },
  {
   "cell_type": "markdown",
   "metadata": {},
   "source": [
    "그런데 만약 어떤 파일을 여는데 쓰기위한 ('w') 파일 퍼미션 대신 열기위한 ('r') 퍼미션으로 파일을 열어 쓰려고 하다면,"
   ]
  },
  {
   "cell_type": "code",
   "execution_count": 3,
   "metadata": {},
   "outputs": [
    {
     "ename": "ZeroDivisionError",
     "evalue": "division by zero",
     "output_type": "error",
     "traceback": [
      "\u001b[0;31m---------------------------------------------------------------------------\u001b[0m",
      "\u001b[0;31mZeroDivisionError\u001b[0m                         Traceback (most recent call last)",
      "\u001b[0;32m<ipython-input-3-d03a81ddc993>\u001b[0m in \u001b[0;36m<module>\u001b[0;34m()\u001b[0m\n\u001b[1;32m      1\u001b[0m \u001b[0;32mtry\u001b[0m\u001b[0;34m:\u001b[0m\u001b[0;34m\u001b[0m\u001b[0m\n\u001b[1;32m      2\u001b[0m     \u001b[0mf\u001b[0m \u001b[0;34m=\u001b[0m \u001b[0mopen\u001b[0m\u001b[0;34m(\u001b[0m\u001b[0;34m'testfile'\u001b[0m\u001b[0;34m,\u001b[0m\u001b[0;34m'r'\u001b[0m\u001b[0;34m)\u001b[0m\u001b[0;34m\u001b[0m\u001b[0m\n\u001b[0;32m----> 3\u001b[0;31m     \u001b[0;36m5\u001b[0m\u001b[0;34m/\u001b[0m\u001b[0;36m0\u001b[0m\u001b[0;34m\u001b[0m\u001b[0m\n\u001b[0m\u001b[1;32m      4\u001b[0m     \u001b[0mf\u001b[0m\u001b[0;34m.\u001b[0m\u001b[0mwrite\u001b[0m\u001b[0;34m(\u001b[0m\u001b[0;34m'Test write this'\u001b[0m\u001b[0;34m)\u001b[0m\u001b[0;34m\u001b[0m\u001b[0m\n\u001b[1;32m      5\u001b[0m \u001b[0;32mexcept\u001b[0m \u001b[0mIOError\u001b[0m\u001b[0;34m:\u001b[0m\u001b[0;34m\u001b[0m\u001b[0m\n",
      "\u001b[0;31mZeroDivisionError\u001b[0m: division by zero"
     ]
    }
   ],
   "source": [
    "try:\n",
    "    f = open('testfile','r')\n",
    "    5/0\n",
    "    f.write('Test write this')\n",
    "except IOError:\n",
    "    # This will only check for an IOError exception and then execute this print statement\n",
    "   print(\"Error: Could not find file or read data\")\n",
    "else:\n",
    "   print(\"Content written successfully\")\n",
    "   f.close()"
   ]
  },
  {
   "cell_type": "markdown",
   "metadata": {},
   "source": [
    "위에서는 예외가 발생하였을 경우 우리만의 경고를 출력했습니다. 위와 같은 경우는 우리가 이미 어떤 예외의 오류가 발생할 수 있다는 것을 알 경우 가능합니다. 하지만 어떤 오류가 발생할 지 알 수 없는 경우도 있습니다.\n",
    "\n",
    "예를 들어,"
   ]
  },
  {
   "cell_type": "code",
   "execution_count": 4,
   "metadata": {},
   "outputs": [
    {
     "name": "stdout",
     "output_type": "stream",
     "text": [
      "Error: Could not find file or read data: <<class 'io.UnsupportedOperation'>:not writable>\n"
     ]
    }
   ],
   "source": [
    "try:\n",
    "    f = open('testfile','r')\n",
    "    f.write('Test write this')\n",
    "except Exception as e:\n",
    "    # This will check for any exception and then execute this print statement\n",
    "   print(\"Error: Could not find file or read data: <%s:%s>\" % (type(e),str(e)))\n",
    "else:\n",
    "   print(\"Content written successfully\")\n",
    "   f.close()"
   ]
  },
  {
   "cell_type": "markdown",
   "metadata": {},
   "source": [
    "위와 같은 경우에는 특정 지정 예외가 아닌 경우 모든 예외의 경우 이용합니다. \n",
    "\n",
    "또 **try** 구분에서 예외가 발생하는 것과 상관없이 마지막에 어떤 코드가 실행하도록 하고 싶은 경우가 있는데 이 경우에 **finally**를 이용합니다.\n",
    "\n",
    "## finally\n",
    "finally: 블럭은 예외의 발생 유무와 상관없이 마지막에 항상 수행하는 코드의 블럭을 의미합니다.\n",
    "\n",
    "    try:\n",
    "       Code block here\n",
    "       ...\n",
    "       Due to any exception, this code may be skipped!\n",
    "    finally:\n",
    "       This code block would always be executed.\n",
    "\n",
    "예를 들어,"
   ]
  },
  {
   "cell_type": "code",
   "execution_count": 5,
   "metadata": {},
   "outputs": [
    {
     "name": "stdout",
     "output_type": "stream",
     "text": [
      "Always execute finally code blocks\n"
     ]
    }
   ],
   "source": [
    "try:\n",
    "   f = open(\"testfile\", \"w\")\n",
    "   f.write(\"Test write statement\")\n",
    "finally:\n",
    "   print(\"Always execute finally code blocks\")"
   ]
  },
  {
   "cell_type": "markdown",
   "metadata": {},
   "source": [
    "다음의 예를 살펴보겠습니다. 사용자가 정수의 숫자를 입력하면 정상으로 수행하지만 아닌경우 예외가 발생합니다. 두 가지 모든 경우에 finally 구문이 실행되는가 살펴보겠습니다."
   ]
  },
  {
   "cell_type": "code",
   "execution_count": 6,
   "metadata": {
    "collapsed": true
   },
   "outputs": [],
   "source": [
    "def askint():\n",
    "        try:\n",
    "            val = int(input(\"Please enter an integer: \"))\n",
    "        except:\n",
    "            print(\"Looks like you did not enter an integer!\")\n",
    "        else:\n",
    "            print('success')\n",
    "        finally:\n",
    "            print(\"Finally, I executed!\")\n",
    "        print(val)"
   ]
  },
  {
   "cell_type": "code",
   "execution_count": 7,
   "metadata": {},
   "outputs": [
    {
     "name": "stdout",
     "output_type": "stream",
     "text": [
      "Please enter an integer: 1\n",
      "success\n",
      "Finally, I executed!\n",
      "1\n"
     ]
    }
   ],
   "source": [
    "askint()"
   ]
  },
  {
   "cell_type": "code",
   "execution_count": 8,
   "metadata": {},
   "outputs": [
    {
     "name": "stdout",
     "output_type": "stream",
     "text": [
      "Please enter an integer: one\n",
      "Looks like you did not enter an integer!\n",
      "Finally, I executed!\n"
     ]
    },
    {
     "ename": "UnboundLocalError",
     "evalue": "local variable 'val' referenced before assignment",
     "output_type": "error",
     "traceback": [
      "\u001b[0;31m---------------------------------------------------------------------------\u001b[0m",
      "\u001b[0;31mUnboundLocalError\u001b[0m                         Traceback (most recent call last)",
      "\u001b[0;32m<ipython-input-8-6ee53d339e7e>\u001b[0m in \u001b[0;36m<module>\u001b[0;34m()\u001b[0m\n\u001b[0;32m----> 1\u001b[0;31m \u001b[0maskint\u001b[0m\u001b[0;34m(\u001b[0m\u001b[0;34m)\u001b[0m\u001b[0;34m\u001b[0m\u001b[0m\n\u001b[0m",
      "\u001b[0;32m<ipython-input-6-9242f16ae669>\u001b[0m in \u001b[0;36maskint\u001b[0;34m()\u001b[0m\n\u001b[1;32m      8\u001b[0m         \u001b[0;32mfinally\u001b[0m\u001b[0;34m:\u001b[0m\u001b[0;34m\u001b[0m\u001b[0m\n\u001b[1;32m      9\u001b[0m             \u001b[0mprint\u001b[0m\u001b[0;34m(\u001b[0m\u001b[0;34m\"Finally, I executed!\"\u001b[0m\u001b[0;34m)\u001b[0m\u001b[0;34m\u001b[0m\u001b[0m\n\u001b[0;32m---> 10\u001b[0;31m         \u001b[0mprint\u001b[0m\u001b[0;34m(\u001b[0m\u001b[0mval\u001b[0m\u001b[0;34m)\u001b[0m\u001b[0;34m\u001b[0m\u001b[0m\n\u001b[0m",
      "\u001b[0;31mUnboundLocalError\u001b[0m: local variable 'val' referenced before assignment"
     ]
    }
   ],
   "source": [
    "askint()"
   ]
  },
  {
   "cell_type": "markdown",
   "metadata": {},
   "source": [
    "바로 위의 오류인 \n",
    "    UnboundLocalError: local variable 'val' referenced before assignment\n",
    "    \n",
    "는 'val' 이라는 변수가 할당되기 전에 오류가 발생하였는데 그 이후에 출력하려고 함으로써 발생한 것입니다. 따라서 아래와 같이,"
   ]
  },
  {
   "cell_type": "code",
   "execution_count": 9,
   "metadata": {
    "collapsed": true
   },
   "outputs": [],
   "source": [
    "def askint():\n",
    "        try:\n",
    "            val = int(input(\"Please enter an integer: \"))\n",
    "        except:\n",
    "            print(\"Looks like you did not enter an integer!\")\n",
    "            val = int(input(\"Try again-Please enter an integer: \"))\n",
    "        finally:\n",
    "            print(\"Finally, I executed!\")\n",
    "        print(val)"
   ]
  },
  {
   "cell_type": "code",
   "execution_count": 10,
   "metadata": {},
   "outputs": [
    {
     "name": "stdout",
     "output_type": "stream",
     "text": [
      "Please enter an integer: 1\n",
      "Finally, I executed!\n",
      "1\n"
     ]
    }
   ],
   "source": [
    "askint()"
   ]
  },
  {
   "cell_type": "markdown",
   "metadata": {},
   "source": [
    "음.. 그런데 위에서는 단지 한번만 오류 체크를 하게 되어 있지요? 어떻게 하면 계속해서 체크하게 될까요?"
   ]
  },
  {
   "cell_type": "code",
   "execution_count": 11,
   "metadata": {
    "collapsed": true
   },
   "outputs": [],
   "source": [
    "def askint():\n",
    "    while True:\n",
    "        try:\n",
    "            val = int(input(\"Please enter an integer: \"))\n",
    "        except:\n",
    "            print(\"Looks like you did not enter an integer!\")\n",
    "            continue\n",
    "        else:\n",
    "            print('Yep thats an integer!')\n",
    "            break\n",
    "        finally:\n",
    "            print(\"Finally, I executed!\")\n",
    "        print(val)"
   ]
  },
  {
   "cell_type": "code",
   "execution_count": 12,
   "metadata": {},
   "outputs": [
    {
     "name": "stdout",
     "output_type": "stream",
     "text": [
      "Please enter an integer: one\n",
      "Looks like you did not enter an integer!\n",
      "Finally, I executed!\n",
      "Please enter an integer: two\n",
      "Looks like you did not enter an integer!\n",
      "Finally, I executed!\n",
      "Please enter an integer: three\n",
      "Looks like you did not enter an integer!\n",
      "Finally, I executed!\n",
      "Please enter an integer: 23\n",
      "Yep thats an integer!\n",
      "Finally, I executed!\n"
     ]
    }
   ],
   "source": [
    "askint()"
   ]
  },
  {
   "cell_type": "markdown",
   "metadata": {},
   "source": [
    "**수고하셨습니다! 위와같이 파이썬에서 *try*, *except*, *else* 및 *finally*를 이용한 예외처리에 대하여 살펴보았습니다.**"
   ]
  },
  {
   "cell_type": "code",
   "execution_count": 13,
   "metadata": {},
   "outputs": [
    {
     "ename": "OSError",
     "evalue": "my raise error",
     "output_type": "error",
     "traceback": [
      "\u001b[0;31m---------------------------------------------------------------------------\u001b[0m",
      "\u001b[0;31mOSError\u001b[0m                                   Traceback (most recent call last)",
      "\u001b[0;32m<ipython-input-13-eae7d9d2f5fd>\u001b[0m in \u001b[0;36m<module>\u001b[0;34m()\u001b[0m\n\u001b[1;32m      1\u001b[0m \u001b[0;32mwith\u001b[0m \u001b[0mopen\u001b[0m\u001b[0;34m(\u001b[0m\u001b[0;34m'foo.txt'\u001b[0m\u001b[0;34m,\u001b[0m \u001b[0;34m'w'\u001b[0m\u001b[0;34m)\u001b[0m \u001b[0;32mas\u001b[0m \u001b[0mofp\u001b[0m\u001b[0;34m:\u001b[0m\u001b[0;34m\u001b[0m\u001b[0m\n\u001b[1;32m      2\u001b[0m     \u001b[0mofp\u001b[0m\u001b[0;34m.\u001b[0m\u001b[0mwrite\u001b[0m\u001b[0;34m(\u001b[0m\u001b[0;34m'abcde foo\\n'\u001b[0m\u001b[0;34m)\u001b[0m\u001b[0;34m\u001b[0m\u001b[0m\n\u001b[0;32m----> 3\u001b[0;31m     \u001b[0;32mraise\u001b[0m \u001b[0mIOError\u001b[0m\u001b[0;34m(\u001b[0m\u001b[0;34m'my raise error'\u001b[0m\u001b[0;34m)\u001b[0m\u001b[0;34m\u001b[0m\u001b[0m\n\u001b[0m",
      "\u001b[0;31mOSError\u001b[0m: my raise error"
     ]
    }
   ],
   "source": [
    "with open('foo.txt', 'w') as ofp:\n",
    "    ofp.write('abcde foo\\n')\n",
    "    raise IOError('my raise error')"
   ]
  },
  {
   "cell_type": "code",
   "execution_count": null,
   "metadata": {
    "collapsed": true
   },
   "outputs": [],
   "source": []
  }
 ],
 "metadata": {
  "kernelspec": {
   "display_name": "Python 3",
   "language": "python",
   "name": "python3"
  },
  "language_info": {
   "codemirror_mode": {
    "name": "ipython",
    "version": 3
   },
   "file_extension": ".py",
   "mimetype": "text/x-python",
   "name": "python",
   "nbconvert_exporter": "python",
   "pygments_lexer": "ipython3",
   "version": "3.6.2"
  }
 },
 "nbformat": 4,
 "nbformat_minor": 1
}
